Workbook
Name solver_rhs5: Degrau!$I$26
Name solver_lhs1: Degrau!$C$10:$E$10
Name solver_lhs4: Degrau!$D$11:$E$11
Name solver_lhs10: Degrau!$J$9
Name solver_lhs9: Degrau!$J$13
Name solver_lhs3: Degrau!$D$11:$E$11
Name solver_rhs10: Degrau!$L$1
Name solver_rhs3: Degrau!$G$27
Name solver_opt: Degrau!$C$26
Name solver_lhs2: Degrau!$C$10:$E$10
Name solver_rhs7: Degrau!$L$1
Name solver_rhs8: Degrau!$L$1
Name solver_lhs6: Degrau!$J$10
Name solver_rhs6: Degrau!$L$1
Name solver_lhs5: Degrau!$I$27
Name solver_rhs9: Degrau!$L$1
Name solver_lhs7: Degrau!$J$11
Name solver_rhs1: Degrau!$G$27
Name solver_lhs8: Degrau!$J$12

Sheet Degrau
C1: z2 | D1: z1 | E1: z0 | G1: Ts(ms) | H1: Tf(s) | I1: JURI | K1: delta | L1: 1e-05
C2: bo | D2: b1 | E2: b2 | G2: 100 | H2: 4
A3: G(z) | C3: 0.5 | D3: 0.5 | E3: 0.5 | I3: a0 | J3: =C20 -> 1 | L3: b0 | M3: =J7*J4-J6*J3 -> 0 | O3: c0 | P3: =M6*M4-M3*M5 -> 0.5
C4: 1 | D4: 0.5 | E4: 0.5 | I4: a1 | J4: =D20 -> 0.5 | L4: b1 | M4: =J7*J5-J3*J5 -> -0.5 | O4: c1 | P4: =M6*M5-M3*M4 -> 0.5
C5: 1 | D5: a1 | E5: a2 | I5: a2 | J5: =E20 -> 0.5 | L5: b2 | M5: =J7*J6-J3*J4 -> -0.5 | O5: c2 | P5: =M6^2-M3^2 -> 1
C6: z2 | D6: z1 | E6: z0 | I6: a3 | J6: =F20 -> 0 | L6: b3 | M6: =J7^2-J3^2 -> -1
I7: a4 | J7: =G20 -> 0
C8: z2 | D8: z1 | E8: z0
C9: bo | D9: b1 | E9: b2 | I9: a0-|a4| | J9: =J3-ABS(J7) -> 1
A10: Gc(z) | C10: 0 | D10: 0 | E10: 0 | F10: Num(1) | G10: =E10+D10+C10 -> 0 | I10: P(1) | J10: =SUM(J3:J7) -> 2
C11: 1 | D11: 0 | E11: 0 | F11: Den(1) | G11: =E11+D11+C11 -> 1 | I11: P(-1) | J11: =J3-J4+J5-J6+J7 -> 1
C12: 1 | D12: a1 | E12: a2 | F12: Gcz(1) | G12: =G10/G11 -> 0 | I12: |b3|-|b0| | J12: =ABS(M6)-ABS(M3) -> 1
C13: z2 | D13: z1 | E13: z0 | I13: |c2|-|c0| | J13: =ABS(P5)-ABS(P3) -> 0.5
C15: z4 | D15: z3 | E15: z2 | F15: z1 | G15: z0
A16: G(z)*Gc(z) | C16: =C10*C3 -> 0 | D16: =C10*D3+C3*D10 -> 0 | E16: =C10*E3+D10*D3+E10*C3 -> 0 | F16: =D10*E3+D3*E10 -> 0 | G16: =E10*E3 -> 0 | K16: -2
C17: 1 | D17: =D11+D4 -> 0.5 | E17: =E4+E11+D4*D11 -> 0.5 | F17: =D11*E4+E11*D4 -> 0 | G17: =E11*E4 -> 0
C18: z4 | D18: z3 | E18: z2 | F18: z1 | G18: z0
A19: T(z) | C19: =C16 -> 0 | D19: =D16 -> 0 | E19: =E16 -> 0 | F19: =F16 -> 0 | G19: =G16 -> 0
C20: =C17+C16 -> 1 | D20: =D17+D16 -> 0.5 | E20: =E17+E16 -> 0.5 | F20: =F17+F16 -> 0 | G20: =G17+G16 -> 0
C21: z4 | D21: z3 | E21: z2 | F21: z1 | G21: z0
A22: T(z)/G(z) | C22: =C10*C4 -> 0 | D22: =C10*D4+C4*D10 -> 0 | E22: =C10*E4+D10*D4+E10*C4 -> 0 | F22: =D10*E4+D4*E10 -> 0 | G22: =E10*E4 -> 0
C23: =C20+C19 -> 1 | D23: =D20+D19 -> 0.5 | E23: =E20 -> 0.5 | F23: =F20+F19 -> 0 | G23: =G20+G19 -> 0
C24: z4 | D24: z3 | E24: z2 | F24: z1 | G24: z0
A26: ISE TIA | C26: =SUM(H34:H74)*G2/(1000*H2) -> 1.025 | D26: Valor mínimo de coeficiente | G26: -3 | H26: Máx U limite | I26: 10
D27: Valor máximo de coeficiente | G27: 3 | H27: Máx U real | I27: =MAX(G30:G134) -> 0
A29: t[s] | B29: k | C29: R(k) | D29: yd(k) | E29: Yest(k) | F29: u(k) | G29: abs(u) | H29: Erro^2
A30: 0 | B30: -4 | C30: 0 | D30: 0 | E30: 0 | F30: =E30 -> 0 | G30: =ABS(F30) -> 0 | H30: 0
A31: 0 | B31: -3 | C31: 0 | D31: 0 | E31: 0 | F31: =E31 -> 0 | G31: =ABS(F31) -> 0 | H31: 0
A32: 0 | B32: -2 | C32: 0 | D32: 0 | E32: 0 | F32: =E32 -> 0 | G32: =ABS(F32) -> 0 | H32: 0
A33: 0 | B33: -1 | C33: 0 | D33: 0 | E33: 0 | F33: =E33 -> 0 | G33: =ABS(F33) -> 0 | H33: 0
A34: 0 | B34: 0 | C34: 1 | D34: 1 | E34: =($C$19*C34+$D$19*C33+$E$19*C32+$F$19*C31+$G$19*C30-$D$20*E33-$E$20*E32-$F$20*E31-$G$20*E30)/$C$20 -> 0 | F34: =($C$22*C34+$D$22*C33+$E$22*C32+$F$22*C31+$G$22*C30-$D$23*F33-$E$23*F32-$F$23*F31-$G$23*F30)/$C$23 -> 0 | G34: =ABS(F34) -> 0 | H34: =(E34-D34)^2 -> 1
A35: =A34+$G$2/1000 -> 0.1 | B35: =B34+1 -> 1 | C35: 1 | D35: 1 | E35: =($C$19*C35+$D$19*C34+$E$19*C33+$F$19*C32+$G$19*C31-$D$20*E34-$E$20*E33-$F$20*E32-$G$20*E31)/$C$20 -> 0 | F35: =($C$22*C35+$D$22*C34+$E$22*C33+$F$22*C32+$G$22*C31-$D$23*F34-$E$23*F33-$F$23*F32-$G$23*F31)/$C$23 -> 0 | G35: =ABS(F35) -> 0 | H35: =(E35-D35)^2 -> 1
A36: =A35+$G$2/1000 -> 0.2 | B36: =B35+1 -> 2 | C36: 1 | D36: 1 | E36: =($C$19*C36+$D$19*C35+$E$19*C34+$F$19*C33+$G$19*C32-$D$20*E35-$E$20*E34-$F$20*E33-$G$20*E32)/$C$20 -> 0 | F36: =($C$22*C36+$D$22*C35+$E$22*C34+$F$22*C33+$G$22*C32-$D$23*F35-$E$23*F34-$F$23*F33-$G$23*F32)/$C$23 -> 0 | G36: =ABS(F36) -> 0 | H36: =(E36-D36)^2 -> 1
A37: =A36+$G$2/1000 -> 0.3 | B37: =B36+1 -> 3 | C37: 1 | D37: 1 | E37: =($C$19*C37+$D$19*C36+$E$19*C35+$F$19*C34+$G$19*C33-$D$20*E36-$E$20*E35-$F$20*E34-$G$20*E33)/$C$20 -> 0 | F37: =($C$22*C37+$D$22*C36+$E$22*C35+$F$22*C34+$G$22*C33-$D$23*F36-$E$23*F35-$F$23*F34-$G$23*F33)/$C$23 -> 0 | G37: =ABS(F37) -> 0 | H37: =(E37-D37)^2 -> 1
A38: =A37+$G$2/1000 -> 0.4 | B38: =B37+1 -> 4 | C38: 1 | D38: 1 | E38: =($C$19*C38+$D$19*C37+$E$19*C36+$F$19*C35+$G$19*C34-$D$20*E37-$E$20*E36-$F$20*E35-$G$20*E34)/$C$20 -> 0 | F38: =($C$22*C38+$D$22*C37+$E$22*C36+$F$22*C35+$G$22*C34-$D$23*F37-$E$23*F36-$F$23*F35-$G$23*F34)/$C$23 -> 0 | G38: =ABS(F38) -> 0 | H38: =(E38-D38)^2 -> 1
A39: =A38+$G$2/1000 -> 0.5 | B39: =B38+1 -> 5 | C39: 1 | D39: 1 | E39: =($C$19*C39+$D$19*C38+$E$19*C37+$F$19*C36+$G$19*C35-$D$20*E38-$E$20*E37-$F$20*E36-$G$20*E35)/$C$20 -> 0 | F39: =($C$22*C39+$D$22*C38+$E$22*C37+$F$22*C36+$G$22*C35-$D$23*F38-$E$23*F37-$F$23*F36-$G$23*F35)/$C$23 -> 0 | G39: =ABS(F39) -> 0 | H39: =(E39-D39)^2 -> 1
A40: =A39+$G$2/1000 -> 0.6 | B40: =B39+1 -> 6 | C40: 1 | D40: 1 | E40: =($C$19*C40+$D$19*C39+$E$19*C38+$F$19*C37+$G$19*C36-$D$20*E39-$E$20*E38-$F$20*E37-$G$20*E36)/$C$20 -> 0 | F40: =($C$22*C40+$D$22*C39+$E$22*C38+$F$22*C37+$G$22*C36-$D$23*F39-$E$23*F38-$F$23*F37-$G$23*F36)/$C$23 -> 0 | G40: =ABS(F40) -> 0 | H40: =(E40-D40)^2 -> 1
A41: =A40+$G$2/1000 -> 0.7 | B41: =B40+1 -> 7 | C41: 1 | D41: 1 | E41: =($C$19*C41+$D$19*C40+$E$19*C39+$F$19*C38+$G$19*C37-$D$20*E40-$E$20*E39-$F$20*E38-$G$20*E37)/$C$20 -> 0 | F41: =($C$22*C41+$D$22*C40+$E$22*C39+$F$22*C38+$G$22*C37-$D$23*F40-$E$23*F39-$F$23*F38-$G$23*F37)/$C$23 -> 0 | G41: =ABS(F41) -> 0 | H41: =(E41-D41)^2 -> 1
A42: =A41+$G$2/1000 -> 0.8 | B42: =B41+1 -> 8 | C42: 1 | D42: 1 | E42: =($C$19*C42+$D$19*C41+$E$19*C40+$F$19*C39+$G$19*C38-$D$20*E41-$E$20*E40-$F$20*E39-$G$20*E38)/$C$20 -> 0 | F42: =($C$22*C42+$D$22*C41+$E$22*C40+$F$22*C39+$G$22*C38-$D$23*F41-$E$23*F40-$F$23*F39-$G$23*F38)/$C$23 -> 0 | G42: =ABS(F42) -> 0 | H42: =(E42-D42)^2 -> 1
A43: =A42+$G$2/1000 -> 0.9 | B43: =B42+1 -> 9 | C43: 1 | D43: 1 | E43: =($C$19*C43+$D$19*C42+$E$19*C41+$F$19*C40+$G$19*C39-$D$20*E42-$E$20*E41-$F$20*E40-$G$20*E39)/$C$20 -> 0 | F43: =($C$22*C43+$D$22*C42+$E$22*C41+$F$22*C40+$G$22*C39-$D$23*F42-$E$23*F41-$F$23*F40-$G$23*F39)/$C$23 -> 0 | G43: =ABS(F43) -> 0 | H43: =(E43-D43)^2 -> 1
...

Sheet __OpenSolverCache__

Sheet __OpenSolver__
A1: =ModelSheet=Degrau!A:Z -> #NAME?
A2: =OpenSolver_AdjNum=2 -> #NAME?
A3: =OpenSolver_ChosenSolver=Google -> #NAME?
A4: =OpenSolver_FastBuild=0 -> #NAME?
A5: =OpenSolver_LinearityCheck=1 -> #NAME?
A6: =solver_adj=Degrau!C10:E10 -> #NAME?
A7: =solver_adj1=Degrau!D11:E11 -> #NAME?
A8: =solver_lhs1=Degrau!C10:E10 -> #NAME?
A9: =solver_lhs10=Degrau!J9 -> #NAME?
A10: =solver_lhs2=Degrau!D11:E11 -> #NAME?
A11: =solver_lhs3=Degrau!D11:E11 -> #NAME?
A12: =solver_lhs4=Degrau!C10:E10 -> #NAME?
A13: =solver_lhs5=Degrau!I27 -> #NAME?
A14: =solver_lhs6=Degrau!J10 -> #NAME?
A15: =solver_lhs7=Degrau!J11 -> #NAME?
A16: =solver_lhs8=Degrau!J12 -> #NAME?
A17: =solver_lhs9=Degrau!J13 -> #NAME?
A18: =solver_neg=1 -> #NAME?
A19: =solver_num=10 -> #NAME?
A20: =solver_opt=Degrau!C26 -> #NAME?
A21: =solver_rel1=1 -> #NAME?
A22: =solver_rel10=3 -> #NAME?
A23: =solver_rel2=3 -> #NAME?
A24: =solver_rel3=1 -> #NAME?
A25: =solver_rel4=3 -> #NAME?
A26: =solver_rel5=1 -> #NAME?
A27: =solver_rel6=3 -> #NAME?
A28: =solver_rel7=3 -> #NAME?
A29: =solver_rel8=3 -> #NAME?
A30: =solver_rel9=3 -> #NAME?
A31: =solver_rhs1=Degrau!G27 -> #NAME?
A32: =solver_rhs10=Degrau!L1 -> #NAME?
A33: =solver_rhs2=Degrau!K16 -> #NAME?
A34: =solver_rhs3=Degrau!G27 -> #NAME?
A35: =solver_rhs4=Degrau!K16 -> #NAME?
A36: =solver_rhs5=Degrau!I26 -> #NAME?
A37: =solver_rhs6=Degrau!L1 -> #NAME?
A38: =solver_rhs7=Degrau!L1 -> #NAME?
A39: =solver_rhs8=Degrau!L1 -> #NAME?
A40: =solver_rhs9=Degrau!L1 -> #NAME?
...
